Workbook

Sheet 01_RAW_DATA
A1: Order_ID | B1: Order_Date | C1: Customer_ID | D1: City | E1: State | F1: Pincode | G1: Medicine_ID | H1: Medicine_Name | I1: Category | J1: Brand | K1: Prescription_Required | L1: Quantity | M1: Unit_Price | N1: Discount_Pct | O1: Tax_Pct | P1: Payment_Mode | Q1: Order_Status | R1: Duplicate_Check | S1: Transaction_ID | T1: Transaction_ID_Count | U1: Gross_Amount | V1: Discount_Amount | W1: Net_Amount_Before_Tax | X1: Tax_Amount | Y1: Final_Amount | Z1: Delivered_Customer_Count
A2: ORD100001 | B2: 45946 | C2: CUST00457 | D2: Delhi | E2: Delhi | F2: 110085 | G2: MED024 | H2: Iron + Folic Acid | I2: Women's Health | J2: Abbott | K2: No | L2: 1 | M2: 126.94 | N2: 10 | O2: 18 | P2: UPI | Q2: Cancelled | R2: =COUNTIFS($A$2:$A$8001,A2,$B$2:$B$8001,B2,$C$2:$C$8001,C2,$G$2:$G$8001,G2) -> 1 | S2: =A2&"_"&TEXT(B2,"yyyymmdd")&"_"&C2&"_"&G2 -> ORD100001_20251016_CUST00457_MED024 | T2: =COUNTIF($S$2:$S$8001,S2) -> 1 | U2: =L2*M2 -> 126.94 | V2: =tbl_Raw_Data[[#This Row],[Discount_Pct]]*tbl_Raw_Data[[#This Row],[Gross_Amount]]/100 -> 12.694 | W2: =tbl_Raw_Data[[#This Row],[Gross_Amount]]-tbl_Raw_Data[[#This Row],[Discount_Amount]] -> 114.246 | X2: =tbl_Raw_Data[[#This Row],[Net_Amount_Before_Tax]]*tbl_Raw_Data[[#This Row],[Tax_Pct]]/100 -> 20.56428 | Y2: =tbl_Raw_Data[[#This Row],[Net_Amount_Before_Tax]]+tbl_Raw_Data[[#This Row],[Tax_Amount]] -> 134.81028 | Z2: =COUNTIFS($C$2:$C$8001,C2,$Q$2:$Q$8001,"Delivered") -> 1
A3: ORD100001 | B3: 45387 | C3: CUST00896 | D3: Hyderabad | E3: Telangana | F3: 500090 | G3: MED017 | H3: Antacid Suspension | I3: Digestive Care | J3: Abbott | K3: No | L3: 2 | M3: 139.26 | N3: 10 | O3: 18 | P3: Net Banking | Q3: Delivered | R3: =COUNTIFS($A$2:$A$8001,A3,$B$2:$B$8001,B3,$C$2:$C$8001,C3,$G$2:$G$8001,G3) -> 1 | S3: =A3&"_"&TEXT(B3,"yyyymmdd")&"_"&C3&"_"&G3 -> ORD100001_20240405_CUST00896_MED017 | T3: =COUNTIF($S$2:$S$8001,S3) -> 1 | U3: =L3*M3 -> 278.52 | V3: =tbl_Raw_Data[[#This Row],[Discount_Pct]]*tbl_Raw_Data[[#This Row],[Gross_Amount]]/100 -> 27.852 | W3: =tbl_Raw_Data[[#This Row],[Gross_Amount]]-tbl_Raw_Data[[#This Row],[Discount_Amount]] -> 250.668 | X3: =tbl_Raw_Data[[#This Row],[Net_Amount_Before_Tax]]*tbl_Raw_Data[[#This Row],[Tax_Pct]]/100 -> 45.12024 | Y3: =tbl_Raw_Data[[#This Row],[Net_Amount_Before_Tax]]+tbl_Raw_Data[[#This Row],[Tax_Amount]] -> 295.78824 | Z3: =COUNTIFS($C$2:$C$8001,C3,$Q$2:$Q$8001,"Delivered") -> 1
A4: ORD100003 | B4: 45576 | C4: CUST03316 | D4: Indore | E4: Madhya Pradesh | F4: 452010 | G4: MED001 | H4: Paracetamol 500mg | I4: Fever & Cold | J4: Cipla | K4: No | L4: 3 | M4: 27.69 | N4: 5 | O4: 5 | P4: Credit Card | Q4: Processing | R4: =COUNTIFS($A$2:$A$8001,A4,$B$2:$B$8001,B4,$C$2:$C$8001,C4,$G$2:$G$8001,G4) -> 1 | S4: =A4&"_"&TEXT(B4,"yyyymmdd")&"_"&C4&"_"&G4 -> ORD100003_20241011_CUST03316_MED001 | T4: =COUNTIF($S$2:$S$8001,S4) -> 1 | U4: =L4*M4 -> 83.07 | V4: =tbl_Raw_Data[[#This Row],[Discount_Pct]]*tbl_Raw_Data[[#This Row],[Gross_Amount]]/100 -> 4.1535 | W4: =tbl_Raw_Data[[#This Row],[Gross_Amount]]-tbl_Raw_Data[[#This Row],[Discount_Amount]] -> 78.9165 | X4: =tbl_Raw_Data[[#This Row],[Net_Amount_Before_Tax]]*tbl_Raw_Data[[#This Row],[Tax_Pct]]/100 -> 3.945825 | Y4: =tbl_Raw_Data[[#This Row],[Net_Amount_Before_Tax]]+tbl_Raw_Data[[#This Row],[Tax_Amount]] -> 82.862325 | Z4: =COUNTIFS($C$2:$C$8001,C4,$Q$2:$Q$8001,"Delivered") -> 1
A5: ORD100003 | B5: 45681 | C5: CUST00397 | D5: Pune | E5: Maharashtra | F5: 411057 | G5: MED028 | H5: B-Complex Tablets | I5: Vitamins & Supplements | J5: Abbott | K5: No | L5: 1 | M5: 104.66 | N5: 0 | O5: 12 | P5: UPI | Q5: Cancelled | R5: =COUNTIFS($A$2:$A$8001,A5,$B$2:$B$8001,B5,$C$2:$C$8001,C5,$G$2:$G$8001,G5) -> 1 | S5: =A5&"_"&TEXT(B5,"yyyymmdd")&"_"&C5&"_"&G5 -> ORD100003_20250124_CUST00397_MED028 | T5: =COUNTIF($S$2:$S$8001,S5) -> 1 | U5: =L5*M5 -> 104.66 | V5: =tbl_Raw_Data[[#This Row],[Discount_Pct]]*tbl_Raw_Data[[#This Row],[Gross_Amount]]/100 -> 0 | W5: =tbl_Raw_Data[[#This Row],[Gross_Amount]]-tbl_Raw_Data[[#This Row],[Discount_Amount]] -> 104.66 | X5: =tbl_Raw_Data[[#This Row],[Net_Amount_Before_Tax]]*tbl_Raw_Data[[#This Row],[Tax_Pct]]/100 -> 12.5592 | Y5: =tbl_Raw_Data[[#This Row],[Net_Amount_Before_Tax]]+tbl_Raw_Data[[#This Row],[Tax_Amount]] -> 117.2192 | Z5: =COUNTIFS($C$2:$C$8001,C5,$Q$2:$Q$8001,"Delivered") -> 1
A6: ORD100003 | B6: 45592 | C6: CUST03398 | D6: Chandigarh | E6: Chandigarh | F6: 160001 | G6: MED020 | H6: Levocetirizine 5mg | I6: Allergy Care | J6: Dr. Reddy's | K6: Yes | L6: 4 | M6: 53.77 | N6: 0 | O6: 5 | P6: Wallet | Q6: Delivered | R6: =COUNTIFS($A$2:$A$8001,A6,$B$2:$B$8001,B6,$C$2:$C$8001,C6,$G$2:$G$8001,G6) -> 1 | S6: =A6&"_"&TEXT(B6,"yyyymmdd")&"_"&C6&"_"&G6 -> ORD100003_20241027_CUST03398_MED020 | T6: =COUNTIF($S$2:$S$8001,S6) -> 1 | U6: =L6*M6 -> 215.08 | V6: =tbl_Raw_Data[[#This Row],[Discount_Pct]]*tbl_Raw_Data[[#This Row],[Gross_Amount]]/100 -> 0 | W6: =tbl_Raw_Data[[#This Row],[Gross_Amount]]-tbl_Raw_Data[[#This Row],[Discount_Amount]] -> 215.08 | X6: =tbl_Raw_Data[[#This Row],[Net_Amount_Before_Tax]]*tbl_Raw_Data[[#This Row],[Tax_Pct]]/100 -> 10.754 | Y6: =tbl_Raw_Data[[#This Row],[Net_Amount_Before_Tax]]+tbl_Raw_Data[[#This Row],[Tax_Amount]] -> 225.834 | Z6: =COUNTIFS($C$2:$C$8001,C6,$Q$2:$Q$8001,"Delivered") -> 1
A7: ORD100006 | B7: 45373 | C7: CUST00954 | D7: Indore | E7: Madhya Pradesh | F7: 452016 | G7: MED004 | H7: Azithromycin 500mg | I7: Antibiotics | J7: Sun Pharma | K7: Yes | L7: 1 | M7: 110.27 | N7: 10 | O7: 5 | P7: Debit Card | Q7: Delivered | R7: =COUNTIFS($A$2:$A$8001,A7,$B$2:$B$8001,B7,$C$2:$C$8001,C7,$G$2:$G$8001,G7) -> 1 | S7: =A7&"_"&TEXT(B7,"yyyymmdd")&"_"&C7&"_"&G7 -> ORD100006_20240322_CUST00954_MED004 | T7: =COUNTIF($S$2:$S$8001,S7) -> 1 | U7: =L7*M7 -> 110.27 | V7: =tbl_Raw_Data[[#This Row],[Discount_Pct]]*tbl_Raw_Data[[#This Row],[Gross_Amount]]/100 -> 11.027 | W7: =tbl_Raw_Data[[#This Row],[Gross_Amount]]-tbl_Raw_Data[[#This Row],[Discount_Amount]] -> 99.243 | X7: =tbl_Raw_Data[[#This Row],[Net_Amount_Before_Tax]]*tbl_Raw_Data[[#This Row],[Tax_Pct]]/100 -> 4.96215 | Y7: =tbl_Raw_Data[[#This Row],[Net_Amount_Before_Tax]]+tbl_Raw_Data[[#This Row],[Tax_Amount]] -> 104.20515 | Z7: =COUNTIFS($C$2:$C$8001,C7,$Q$2:$Q$8001,"Delivered") -> 1
A8: ORD100007 | B8: 46010 | C8: CUST02800 | D8: Chandigarh | E8: Chandigarh | F8: 160022 | G8: MED003 | H8: Cetirizine 10mg | I8: Allergy Care | J8: Dr. Reddy's | K8: No | L8: 2 | M8: 25.93 | N8: 10 | O8: 5 | P8: Net Banking | Q8: Delivered | R8: =COUNTIFS($A$2:$A$8001,A8,$B$2:$B$8001,B8,$C$2:$C$8001,C8,$G$2:$G$8001,G8) -> 1 | S8: =A8&"_"&TEXT(B8,"yyyymmdd")&"_"&C8&"_"&G8 -> ORD100007_20251219_CUST02800_MED003 | T8: =COUNTIF($S$2:$S$8001,S8) -> 1 | U8: =L8*M8 -> 51.86 | V8: =tbl_Raw_Data[[#This Row],[Discount_Pct]]*tbl_Raw_Data[[#This Row],[Gross_Amount]]/100 -> 5.186 | W8: =tbl_Raw_Data[[#This Row],[Gross_Amount]]-tbl_Raw_Data[[#This Row],[Discount_Amount]] -> 46.674 | X8: =tbl_Raw_Data[[#This Row],[Net_Amount_Before_Tax]]*tbl_Raw_Data[[#This Row],[Tax_Pct]]/100 -> 2.3337 | Y8: =tbl_Raw_Data[[#This Row],[Net_Amount_Before_Tax]]+tbl_Raw_Data[[#This Row],[Tax_Amount]] -> 49.0077 | Z8: =COUNTIFS($C$2:$C$8001,C8,$Q$2:$Q$8001,"Delivered") -> 2
A9: ORD100008 | B9: 45947 | C9: CUST02819 | D9: Jaipur | E9: Rajasthan | F9: 302001 | G9: MED008 | H9: Atorvastatin 10mg | I9: Cardiac Care | J9: Zydus | K9: Yes | L9: 2 | M9: 68.67 | N9: 10 | O9: 5 | P9: Debit Card | Q9: Cancelled | R9: =COUNTIFS($A$2:$A$8001,A9,$B$2:$B$8001,B9,$C$2:$C$8001,C9,$G$2:$G$8001,G9) -> 1 | S9: =A9&"_"&TEXT(B9,"yyyymmdd")&"_"&C9&"_"&G9 -> ORD100008_20251017_CUST02819_MED008 | T9: =COUNTIF($S$2:$S$8001,S9) -> 1 | U9: =L9*M9 -> 137.34 | V9: =tbl_Raw_Data[[#This Row],[Discount_Pct]]*tbl_Raw_Data[[#This Row],[Gross_Amount]]/100 -> 13.734 | W9: =tbl_Raw_Data[[#This Row],[Gross_Amount]]-tbl_Raw_Data[[#This Row],[Discount_Amount]] -> 123.606 | X9: =tbl_Raw_Data[[#This Row],[Net_Amount_Before_Tax]]*tbl_Raw_Data[[#This Row],[Tax_Pct]]/100 -> 6.1803 | Y9: =tbl_Raw_Data[[#This Row],[Net_Amount_Before_Tax]]+tbl_Raw_Data[[#This Row],[Tax_Amount]] -> 129.7863 | Z9: =COUNTIFS($C$2:$C$8001,C9,$Q$2:$Q$8001,"Delivered") -> 3
A10: ORD100009 | B10: 45508 | C10: CUST02324 | D10: Surat | E10: Gujarat | F10: 395010 | G10: MED023 | H10: Sunscreen SPF 50 | I10: Skin Care | J10: Lacto Calamine | K10: No | L10: 1 | M10: 316.03 | N10: 5 | O10: 18 | P10: Credit Card | Q10: Delivered | R10: =COUNTIFS($A$2:$A$8001,A10,$B$2:$B$8001,B10,$C$2:$C$8001,C10,$G$2:$G$8001,G10) -> 1 | S10: =A10&"_"&TEXT(B10,"yyyymmdd")&"_"&C10&"_"&G10 -> ORD100009_20240804_CUST02324_MED023 | T10: =COUNTIF($S$2:$S$8001,S10) -> 1 | U10: =L10*M10 -> 316.03 | V10: =tbl_Raw_Data[[#This Row],[Discount_Pct]]*tbl_Raw_Data[[#This Row],[Gross_Amount]]/100 -> 15.8015 | W10: =tbl_Raw_Data[[#This Row],[Gross_Amount]]-tbl_Raw_Data[[#This Row],[Discount_Amount]] -> 300.2285 | X10: =tbl_Raw_Data[[#This Row],[Net_Amount_Before_Tax]]*tbl_Raw_Data[[#This Row],[Tax_Pct]]/100 -> 54.04113 | Y10: =tbl_Raw_Data[[#This Row],[Net_Amount_Before_Tax]]+tbl_Raw_Data[[#This Row],[Tax_Amount]] -> 354.26963 | Z10: =COUNTIFS($C$2:$C$8001,C10,$Q$2:$Q$8001,"Delivered") -> 2
A11: ORD100009 | B11: 45866 | C11: CUST02208 | D11: Chennai | E11: Tamil Nadu | F11: 600018 | G11: MED024 | H11: Iron + Folic Acid | I11: Women's Health | J11: Abbott | K11: No | L11: 2 | M11: 151.53 | N11: 5 | O11: 5 | P11: Cash on Delivery | Q11: Returned | R11: =COUNTIFS($A$2:$A$8001,A11,$B$2:$B$8001,B11,$C$2:$C$8001,C11,$G$2:$G$8001,G11) -> 1 | S11: =A11&"_"&TEXT(B11,"yyyymmdd")&"_"&C11&"_"&G11 -> ORD100009_20250728_CUST02208_MED024 | T11: =COUNTIF($S$2:$S$8001,S11) -> 1 | U11: =L11*M11 -> 303.06 | V11: =tbl_Raw_Data[[#This Row],[Discount_Pct]]*tbl_Raw_Data[[#This Row],[Gross_Amount]]/100 -> 15.153 | W11: =tbl_Raw_Data[[#This Row],[Gross_Amount]]-tbl_Raw_Data[[#This Row],[Discount_Amount]] -> 287.907 | X11: =tbl_Raw_Data[[#This Row],[Net_Amount_Before_Tax]]*tbl_Raw_Data[[#This Row],[Tax_Pct]]/100 -> 14.39535 | Y11: =tbl_Raw_Data[[#This Row],[Net_Amount_Before_Tax]]+tbl_Raw_Data[[#This Row],[Tax_Amount]] -> 302.30235 | Z11: =COUNTIFS($C$2:$C$8001,C11,$Q$2:$Q$8001,"Delivered") -> 4
A12: ORD100009 | B12: 45340 | C12: CUST00450 | D12: Bengaluru | E12: Karnataka | F12: 560066 | G12: MED021 | H12: Clotrimazole Cream | I12: Skin Care | J12: Cipla | K12: No | L12: 1 | M12: 87.23 | N12: 5 | O12: 12 | P12: Cash on Delivery | Q12: Returned | R12: =COUNTIFS($A$2:$A$8001,A12,$B$2:$B$8001,B12,$C$2:$C$8001,C12,$G$2:$G$8001,G12) -> 1 | S12: =A12&"_"&TEXT(B12,"yyyymmdd")&"_"&C12&"_"&G12 -> ORD100009_20240218_CUST00450_MED021 | T12: =COUNTIF($S$2:$S$8001,S12) -> 1 | U12: =L12*M12 -> 87.23 | V12: =tbl_Raw_Data[[#This Row],[Discount_Pct]]*tbl_Raw_Data[[#This Row],[Gross_Amount]]/100 -> 4.3615 | W12: =tbl_Raw_Data[[#This Row],[Gross_Amount]]-tbl_Raw_Data[[#This Row],[Discount_Amount]] -> 82.8685 | X12: =tbl_Raw_Data[[#This Row],[Net_Amount_Before_Tax]]*tbl_Raw_Data[[#This Row],[Tax_Pct]]/100 -> 9.94422 | Y12: =tbl_Raw_Data[[#This Row],[Net_Amount_Before_Tax]]+tbl_Raw_Data[[#This Row],[Tax_Amount]] -> 92.81272 | Z12: =COUNTIFS($C$2:$C$8001,C12,$Q$2:$Q$8001,"Delivered") -> 3
A13: ORD100012 | B13: 45858 | C13: CUST00048 | D13: Chandigarh | E13: Chandigarh | F13: 160019 | G13: MED024 | H13: Iron + Folic Acid | I13: Women's Health | J13: Abbott | K13: No | L13: 1 | M13: 151.05 | N13: 10 | O13: 18 | P13: UPI | Q13: Delivered | R13: =COUNTIFS($A$2:$A$8001,A13,$B$2:$B$8001,B13,$C$2:$C$8001,C13,$G$2:$G$8001,G13) -> 1 | S13: =A13&"_"&TEXT(B13,"yyyymmdd")&"_"&C13&"_"&G13 -> ORD100012_20250720_CUST00048_MED024 | T13: =COUNTIF($S$2:$S$8001,S13) -> 1 | U13: =L13*M13 -> 151.05 | V13: =tbl_Raw_Data[[#This Row],[Discount_Pct]]*tbl_Raw_Data[[#This Row],[Gross_Amount]]/100 -> 15.105 | W13: =tbl_Raw_Data[[#This Row],[Gross_Amount]]-tbl_Raw_Data[[#This Row],[Discount_Amount]] -> 135.945 | X13: =tbl_Raw_Data[[#This Row],[Net_Amount_Before_Tax]]*tbl_Raw_Data[[#This Row],[Tax_Pct]]/100 -> 24.4701 | Y13: =tbl_Raw_Data[[#This Row],[Net_Amount_Before_Tax]]+tbl_Raw_Data[[#This Row],[Tax_Amount]] -> 160.4151 | Z13: =COUNTIFS($C$2:$C$8001,C13,$Q$2:$Q$8001,"Delivered") -> 2
... A8001: ORD108000 | B8001: 45830 | C8001: CUST01249 | D8001: Surat | E8001: Gujarat | F8001: 395003 | G8001: MED004 | H8001: Azithromycin 500mg | I8001: Antibiotics | J8001: Sun Pharma | K8001: Yes | L8001: 2 | M8001: 117.7 | N8001: 0 | O8001: 5 | P8001: Credit Card | Q8001: Processing | R8001: =COUNTIFS($A$2:$A$8001,A8001,$B$2:$B$8001,B8001,$C$2:$C$8001,C8001,$G$2:$G$8001,G8001) -> 1 | S8001: =A8001&"_"&TEXT(B8001,"yyyymmdd")&"_"&C8001&"_"&G8001 -> ORD108000_20250622_CUST01249_MED004 | T8001: =COUNTIF($S$2:$S$8001,S8001) -> 1 | U8001: =L8001*M8001 -> 235.4 | V8001: =tbl_Raw_Data[[#This Row],[Discount_Pct]]*tbl_Raw_Data[[#This Row],[Gross_Amount]]/100 -> 0 | W8001: =tbl_Raw_Data[[#This Row],[Gross_Amount]]-tbl_Raw_Data[[#This Row],[Discount_Amount]] -> 235.4 | X8001: =tbl_Raw_Data[[#This Row],[Net_Amount_Before_Tax]]*tbl_Raw_Data[[#This Row],[Tax_Pct]]/100 -> 11.77 | Y8001: =tbl_Raw_Data[[#This Row],[Net_Amount_Before_Tax]]+tbl_Raw_Data[[#This Row],[Tax_Amount]] -> 247.17 | Z8001: =COUNTIFS($C$2:$C$8001,C8001,$Q$2:$Q$8001,"Delivered") -> 0

Sheet 02_DATA QUALITY
A1: DATA QUALITY AUDIT
A3: Check | B3: Expected | C3: Actual | D3: Status
A4: Total Rows | B4: 8000 | C4: =ROWS(tbl_Raw_Data[Order_ID]) -> 8000 | D4: =IF(C4=B4,"PASS","CHECK") -> PASS
A5: Blank Order ID | B5: 0 | C5: =COUNTBLANK(tbl_Raw_Data[Order_ID]) -> 0 | D5: =IF(C5=B5,"PASS","CHECK") -> PASS
A6: Blank Customer ID | B6: 0 | C6: =COUNTBLANK(tbl_Raw_Data[Customer_ID]) -> 0 | D6: =IF(C6=B6,"PASS","CHECK") -> PASS
A7: Blank Order Date | B7: 0 | C7: =COUNTBLANK(tbl_Raw_Data[Order_Date]) -> 0 | D7: =IF(C7=B7,"PASS","CHECK") -> PASS
A8: Blank Medicine ID | B8: 0 | C8: =COUNTBLANK(tbl_Raw_Data[Medicine_ID]) -> 0 | D8: =IF(C8=B8,"PASS","CHECK") -> PASS
A9: Blank Medicine Name | B9: 0 | C9: =COUNTBLANK(tbl_Raw_Data[Medicine_Name]) -> 0 | D9: =IF(C9=B9,"PASS","CHECK") -> PASS
A10: Blank Category | B10: 0 | C10: =COUNTBLANK(tbl_Raw_Data[Category]) -> 0 | D10: =IF(C10=B10,"PASS","CHECK") -> PASS
A11: Blank Quantity | B11: 0 | C11: =COUNTBLANK(tbl_Raw_Data[Quantity]) -> 0 | D11: =IF(C11=B11,"PASS","CHECK") -> PASS
A12: Blank Unit Price | B12: 0 | C12: =COUNTBLANK(tbl_Raw_Data[Unit_Price]) -> 0 | D12: =IF(C12=B12,"PASS","CHECK") -> PASS
A13: Blank Discount % | B13: 0 | C13: =COUNTBLANK(tbl_Raw_Data[Discount_Pct]) -> 0 | D13: =IF(C13=B13,"PASS","CHECK") -> PASS
A14: Blank Tax % | B14: 0 | C14: =COUNTBLANK(tbl_Raw_Data[Tax_Pct]) -> 0 | D14: =IF(C14=B14,"PASS","CHECK") -> PASS
A15: Blank Order Status | B15: 0 | C15: =COUNTBLANK(tbl_Raw_Data[Order_Status]) -> 0 | D15: =IF(C15=B15,"PASS","CHECK") -> PASS
C16: =COUNTBLANK(tbl_Raw_Data[Order_ID]) -> 0 | D16: =IF(C16=B16,"PASS","CHECK") -> PASS
A17: Invalid Quantity | B17: 0 | C17: =COUNTIF(tbl_Raw_Data[Quantity],"<1") -> 0 | D17: =IF(C17=B17,"PASS","CHECK") -> PASS
A18: Invalid Unit Price | B18: 0 | C18: =COUNTIF(tbl_Raw_Data[Unit_Price],"<="&0) -> 0 | D18: =IF(C18=B18,"PASS","CHECK") -> PASS
A19: Invalid Discount % | B19: 0 | C19: =COUNTIF(tbl_Raw_Data[Discount_Pct],"<0")+COUNTIF(tbl_Raw_Data[Discount_Pct],">20") -> 0 | D19: =IF(C19=B19,"PASS","CHECK") -> PASS
A20: Invalid Tax % | B20: 0 | C20: =COUNTIF(tbl_Raw_Data[Tax_Pct],"<5")+COUNTIF(tbl_Raw_Data[Tax_Pct],">18") -> 0 | D20: =IF(C20=B20,"PASS","CHECK") -> PASS
A21: Duplicate Transaction Records | B21: 0 | C21: =COUNTIF(tbl_Raw_Data[Duplicate_Check],">1") -> 0 | D21: =IF(C21=B21,"PASS","CHECK") -> PASS
A22: Duplicate Transaction IDs | B22: 0 | C22: =COUNTIF('01_RAW_DATA'!T2:T8001,">1") -> 0 | D22: =IF(C22=0,"PASS","CHECK") -> PASS
A23: Final Amount Calculation Errors | B23: 0 | C23: =SUMPRODUCT(--(ROUND('01_RAW_DATA'!Y2:Y8001,2)<>ROUND('01_RAW_DATA'!W2:W8001+'01_RAW_DATA'!X2:X8001,2))) -> 0 | D23: =IF(C23=B23,"PASS","CHECK") -> PASS
A25: OVERALL DATA QUALITY STATUS | C25: =IF(COUNTIF(D4:D23,"CHECK")=0,"PASS","CHECK") -> PASS

Sheet 03_CALCULATIONS
A1: HEALTHCARE E-COMMERCE SALES CALCULATIONS
A3: KPI | B3: Value
A4: Total Transactions | B4: =COUNTA(tbl_Raw_Data[Transaction_ID]) -> 8000
A5: Total Customers | B5: =SUMPRODUCT((tbl_Raw_Data[Customer_ID]<>"")/COUNTIF(tbl_Raw_Data[Customer_ID],tbl_Raw_Data[Customer_ID]&"")) -> 3137
A6: Total Units Sold | B6: =SUM(tbl_Raw_Data[Quantity]) -> 16739
A7: Total Gross Sales | B7: =SUM(tbl_Raw_Data[Gross_Amount]) -> 1827525.1
A8: Total Discount Amount | B8: =SUM(tbl_Raw_Data[Discount_Amount]) -> 121834.32
A9: Net Sales Before Tax | B9: =SUM(tbl_Raw_Data[Net_Amount_Before_Tax]) -> 1705690.8
A10: Total Tax Amount | B10: =SUM(tbl_Raw_Data[Tax_Amount]) -> 164168.09
A11: Total Final Sales | B11: =SUM(tbl_Raw_Data[Final_Amount]) -> 1869858.9
A12: Delivered Sales | B12: =SUMIFS(tbl_Raw_Data[Final_Amount],tbl_Raw_Data[Order_Status],"Delivered") -> 1176326.6
A13: Delivered Transactions | B13: =COUNTIF(tbl_Raw_Data[Order_Status],"Delivered") -> 5020
A14: Delivered AOV | B14: =B12/B13 -> 234.32801
A15: Returned Transactions | B15: =COUNTIF(tbl_Raw_Data[Order_Status],"Returned") -> 1022
A16: Cancelled Transactions | B16: =COUNTIF(tbl_Raw_Data[Order_Status],"Cancelled") -> 981
A17: Return Rate | B17: =B15/COUNTA(tbl_Raw_Data[Transaction_ID]) -> 0.12775
A18: Cancellation Rate | B18: =B16/COUNTA(tbl_Raw_Data[Transaction_ID]) -> 0.122625
A19: Non-Delivered Transactions | B19: =COUNTA(tbl_Raw_Data[Transaction_ID])-B13 -> 2980
A20: Non-Delivered Rate | B20: =B19/COUNTA(tbl_Raw_Data[Transaction_ID]) -> 0.3725

Sheet 04_PIVOT_ANALYSIS
A1: HEALTHCARE E-COMMERCE PIVOT ANALYSIS | D1: Order_Status | E1: Delivered | G1: Order_Status | H1: Delivered
A3: Analysis | B3: Purpose | D3: CATEGORY | E3: Sum of Final_Amount | G3: CATEGORY | H3: Sum of Quantity | I3: Sum of Final_Amount
A4: Sales by Category | B4: Category performance | D4: Respiratory Care | E4: 247187.93 | G4: Allergy Care | H4: 665 | I4: 28602.071
A5: Sales by State | B5: Geographic performance | D5: Skin Care | E5: 203342.71 | G5: Antibiotics | H5: 652 | I5: 69195.816
A6: Sales by Payment Mode | B6: Payment behavior | D6: Vitamins & Supplements | E6: 188060.73 | G6: Cardiac Care | H6: 690 | I6: 53880.861
A7: Order Status | B7: Delivered / Returned / Cancelled / Processing | D7: Eye & Ear Care | E7: 99865.364 | G7: Diabetes Care | H7: 674 | I7: 42614.776
A8: Monthly Sales | B8: Sales trend | D8: Digestive Care | E8: 85757.884 | G8: Digestive Care | H8: 1103 | I8: 85757.884
A9: Customer Frequency | B9: Repeat vs One-Time behavior | D9: Women's Health | E9: 79696.161 | G9: Eye & Ear Care | H9: 682 | I9: 99865.364
D10: Antibiotics | E10: 69195.816 | G10: Fever & Cold | H10: 648 | I10: 20782.245
D11: Pain Relief | E11: 57340.066 | G11: Pain Relief | H11: 713 | I11: 57340.066
D12: Cardiac Care | E12: 53880.861 | G12: Respiratory Care | H12: 1472 | I12: 247187.93
D13: Diabetes Care | E13: 42614.776 | G13: Skin Care | H13: 1054 | I13: 203342.71
D14: Allergy Care | E14: 28602.071 | G14: Vitamins & Supplements | H14: 1370 | I14: 188060.73
D15: Fever & Cold | E15: 20782.245 | G15: Women's Health | H15: 765 | I15: 79696.161
D16: Grand Total | E16: 1176326.6 | G16: Grand Total | H16: 10488 | I16: 1176326.6
D18: Order_Status | E18: Delivered
G19: Order_Status | H19: Delivered
D20: STATE | E20: Sum of Final_Amount
D21: Gujarat | E21: 170002.2 | G21: MEDICINE | H21: Sum of Final_Amount | I21: Sum of Quantity
D22: Maharashtra | E22: 152630.31 | G22: Sunscreen SPF 50 | H22: 108434.95 | I22: 355
D23: Uttar Pradesh | E23: 148505.64 | G23: Budesonide Inhaler | H23: 108331.5 | I23: 357
D24: Madhya Pradesh | E24: 86991.338 | G24: Moisturizing Lotion | H24: 67637.787 | I24: 378
D25: Chandigarh | E25: 86781.225 | G25: Lubricating Eye Drops | H25: 64591.148 | I25: 327
D26: Telangana | E26: 86263.004 | G26: Multivitamin Tablets | H26: 59593.323 | I26: 359
D27: West Bengal | E27: 79420.076 | G27: Saline Nasal Spray | H27: 56399.056 | I27: 359
D28: Haryana | E28: 77189.259 | G28: Iron + Folic Acid | H28: 54041.693 | I28: 388
D29: Karnataka | E29: 75306.829 | G29: Antacid Suspension | H29: 49984.435 | I29: 354
D30: Tamil Nadu | E30: 74166.993 | G30: Vitamin D3 60000 IU | H30: 47230.98 | I30: 384
D31: Delhi | E31: 73425.041 | G31: Montelukast 10mg | H31: 43532.592 | I31: 428
D32: Rajasthan | E32: 65644.701 | G32: Calcium + Vitamin D3 | H32: 43437.021 | I32: 291
D33: Grand Total | E33: 1176326.6 | G33: Diclofenac Gel | H33: 39799.164 | I33: 364
G34: Cough Syrup 100ml | H34: 38924.785 | I34: 328
G35: B-Complex Tablets | H35: 37799.411 | I35: 336
G36: Azithromycin 500mg | H36: 37656.671 | I36: 328
G37: Ear Drops | H37: 35274.216 | I37: 355
D38: Order_Status | E38: Delivered | G38: Telmisartan 40mg | H38: 33134.494 | I38: 363
G39: Amoxicillin 500mg | H39: 31539.145 | I39: 324
D40: PAYMENT_MODE | E40: Sum of Final_Amount | G40: Glimepiride 1mg | H40: 28499.957 | I40: 369
D41: Credit Card | E41: 199778.08 | G41: Clotrimazole Cream | H41: 27269.979 | I41: 321
D42: Debit Card | E42: 198788.86 | G42: Mefenamic Acid | H42: 25654.468 | I42: 377
...

Sheet 05_EXCEL_DASHBOARD
A1: HEALTHCARE & E-PHARMACY SALES ANALYTICS
A2: Excel Exploratory Analysis | 2024–2025
A4: TOTAL TRANSACTIONS | C4: TOTAL CUSTOMER | E4: TOTAL FINAL SALES | G4: DELIVERED SALES
A5: ='03_CALCULATIONS'!B4 -> 8000 | C5: ='03_CALCULATIONS'!B5 -> 3137 | E5: ='03_CALCULATIONS'!B11 -> 1869858.9 | G5: ='03_CALCULATIONS'!B12 -> 1176326.6
C7: DELIVERED AOV | E7: NON-DELIVERED RATE
C8: ='03_CALCULATIONS'!B14 -> 234.32801 | E8: ='03_CALCULATIONS'!B20 -> 0.3725
A44: KEY BUSINESS INSIGHTS
A46: 1. Delivered sales are ₹1.18M, while 37.25% of transactions are non-delivered, indicating a significant order-fulfillment opportunity.
A48: 2. Respiratory Care is the highest-selling category, making it a key category for revenue focus.
A50: 3. Repeat customers contribute significantly to delivered business, highlighting the importance of retention and refill strategies.
A52: 4. High return and cancellation volumes should be investigated to improve customer experience and operational efficiency.
